<?xml version="1.0" encoding="UTF-8"?>
<testsuite time="139.94789147377014" tests='4' skipped='0'
name="Test_Asign_Credit_Balance_Page" failures='3' errors='0'><testcase time="43.72067880630493" name="Asign_Credit_Accounts_Tecnologia-Identidad" status="failed"
         classname="Test_Company_Balance_Assign_Credits" >
            <failure message="'global_functions' object has no attribute 'evidence_path'" type="AssertionError">
                    <![CDATA[ Failing step: when I am see the confirmation alert, "The balance transfer among accounts was successful" in "(//div[@class='ant-notification-notice-description'])[1]" ... failed in 2.066s  Location:5
                        {'step_type': 'when', 'name': 'I am see the confirmation alert, "The balance transfer among accounts was successful" in "(//div[@class=\'ant-notification-notice-description\'])[1]"', 'text': 'None', 'status': 'failed', 'duration': 2.066002607345581, 'error_msg': "'global_functions' object has no attribute 'evidence_path'", 'error_lines': ['  File "/usr/local/lib/python3.8/dist-packages/behave/model.py", line 1329, in run\n    match.run(runner.context)\n', '  File "/usr/local/lib/python3.8/dist-packages/behave/matchers.py", line 98, in run\n    self.func(context, *args, **kwargs)\n', '  File "/home/fpalencia/Automations/mientorno/test-pruebas-automatizadas/Project/tests/steps/test_common_step.py", line 26, in test_step_impl\n    context.common_instance.error_message_matches(alert_confirmation, xpath)\n', '  File "/home/fpalencia/Automations/mientorno/test-pruebas-automatizadas/Project/tests/pages/common_page.py", line 37, in error_message_matches\n    self.global_function.attach_screenshot_to_report()\n', '  File "/home/fpalencia/Automations/mientorno/test-pruebas-automatizadas/Project/tests/pages/global_functions.py", line 184, in attach_screenshot_to_report\n    screenshot_path = os.path.join(self.evidence_path, f"{name}.png")\n'], 'hash': 65938931, 'index': 5}
                    ]]>
                </failure><system-out>
            <![CDATA[
            @scenario.begin
                @Test_Company_Balance_Assign_Credits_4   @Test_Company_Balance_Assign_Credits
                scenario: Asign credit accounts tecnologia->Identidad
                given I am on the Balance company page ... passed in 26.92s 
e                when I select &#34;Assign Credit&#34; button ... passed in 4.966s 
                then I see the assign credits screen ... passed in 0.01939s 
                when I select the &#34;Identidad&#34; account ... passed in 6.301s 
                when I enter a valor &#34;10&#34; in the avaliable balanace ... passed in 0.1416s 
                when I click the &#34;Allocate founds&#34; button ... passed in 3.31s 
                when I am see the confirmation alert, &#34;The balance transfer among accounts was successful&#34; in &#34;(//div[@class=&#39;ant-notification-notice-description&#39;])[1]&#34; ... failed in 2.066s 
@scenario.end
            ----------------------------------------------------------------------------------------------------
            ]]>
            </system-out>
        </testcase><testcase time="28.205075979232788" name="Asign_Credit_Accounts_(Error)" status="passed"
         classname="Test_Company_Balance_Assign_Credits" >
            <system-out>
            <![CDATA[
            @scenario.begin
                @smoketest   @Test_Company_Balance_Assign_Credits_1   @Test_Company_Balance_Assign_Credits
                scenario: Asign credit accounts (error)
                given I am on the Balance company page ... passed in 18.21s 
e                when I select &#34;Assign Credit&#34; button ... passed in 4.581s 
                then I see the assign credits screen ... passed in 0.01433s 
                when I click the &#34;Allocate founds&#34; button ... passed in 3.288s 
                then I see the error message &#34;You need to select an account&#34; in &#34;//div[@class=&#39;ant-notification-notice-description&#39;]&#34; ... passed in 2.112s 
@scenario.end
            ----------------------------------------------------------------------------------------------------
            ]]>
            </system-out>
        </testcase><testcase time="33.73076820373535" name="Asign_Credit_Accounts_(Error)" status="failed"
         classname="Test_Company_Balance_Assign_Credits" >
            <failure message="'global_functions' object has no attribute 'evidence_path'" type="AssertionError">
                    <![CDATA[ Failing step: then I see the error message "The value must be greater than zero" in "//div[@class='ant-notification-notice-description']" ... failed in 2.108s  Location:4
                        {'step_type': 'then', 'name': 'I see the error message "The value must be greater than zero" in "//div[@class=\'ant-notification-notice-description\']"', 'text': 'None', 'status': 'failed', 'duration': 2.108131170272827, 'error_msg': "'global_functions' object has no attribute 'evidence_path'", 'error_lines': ['  File "/usr/local/lib/python3.8/dist-packages/behave/model.py", line 1329, in run\n    match.run(runner.context)\n', '  File "/usr/local/lib/python3.8/dist-packages/behave/matchers.py", line 98, in run\n    self.func(context, *args, **kwargs)\n', '  File "/home/fpalencia/Automations/mientorno/test-pruebas-automatizadas/Project/tests/steps/test_common_step.py", line 20, in test_step_impl\n    context.common_instance.error_message_matches(expected_message, xpath)\n', '  File "/home/fpalencia/Automations/mientorno/test-pruebas-automatizadas/Project/tests/pages/common_page.py", line 37, in error_message_matches\n    self.global_function.attach_screenshot_to_report()\n', '  File "/home/fpalencia/Automations/mientorno/test-pruebas-automatizadas/Project/tests/pages/global_functions.py", line 184, in attach_screenshot_to_report\n    screenshot_path = os.path.join(self.evidence_path, f"{name}.png")\n'], 'hash': 85040021, 'index': 4}
                    ]]>
                </failure><system-out>
            <![CDATA[
            @scenario.begin
                @Test_Company_Balance_Assign_Credits_2   @Test_Company_Balance_Assign_Credits
                scenario: Asign credit accounts (error)
                given I am on the Balance company page ... passed in 17.45s 
e                when I select &#34;Assign Credit&#34; button ... passed in 4.519s 
                then I see the assign credits screen ... passed in 0.0422s 
                when I select the &#34;Identidad&#34; account ... passed in 6.322s 
                when I click the &#34;Allocate founds&#34; button ... passed in 3.295s 
                then I see the error message &#34;The value must be greater than zero&#34; in &#34;//div[@class=&#39;ant-notification-notice-description&#39;]&#34; ... failed in 2.108s 
@scenario.end
            ----------------------------------------------------------------------------------------------------
            ]]>
            </system-out>
        </testcase><testcase time="34.29136848449707" name="Asign_Credit_Accounts_(Error)" status="failed"
         classname="Test_Company_Balance_Assign_Credits" >
            <failure message="'global_functions' object has no attribute 'evidence_path'" type="AssertionError">
                    <![CDATA[ Failing step: then I see the error message "An error occurred while transferring balance among accounts" in "//div[@class='ant-notification-notice-description']" ... failed in 2.074s  Location:5
                        {'step_type': 'then', 'name': 'I see the error message "An error occurred while transferring balance among accounts" in "//div[@class=\'ant-notification-notice-description\']"', 'text': 'None', 'status': 'failed', 'duration': 2.0743625164031982, 'error_msg': "'global_functions' object has no attribute 'evidence_path'", 'error_lines': ['  File "/usr/local/lib/python3.8/dist-packages/behave/model.py", line 1329, in run\n    match.run(runner.context)\n', '  File "/usr/local/lib/python3.8/dist-packages/behave/matchers.py", line 98, in run\n    self.func(context, *args, **kwargs)\n', '  File "/home/fpalencia/Automations/mientorno/test-pruebas-automatizadas/Project/tests/steps/test_common_step.py", line 20, in test_step_impl\n    context.common_instance.error_message_matches(expected_message, xpath)\n', '  File "/home/fpalencia/Automations/mientorno/test-pruebas-automatizadas/Project/tests/pages/common_page.py", line 37, in error_message_matches\n    self.global_function.attach_screenshot_to_report()\n', '  File "/home/fpalencia/Automations/mientorno/test-pruebas-automatizadas/Project/tests/pages/global_functions.py", line 184, in attach_screenshot_to_report\n    screenshot_path = os.path.join(self.evidence_path, f"{name}.png")\n'], 'hash': 85040021, 'index': 5}
                    ]]>
                </failure><system-out>
            <![CDATA[
            @scenario.begin
                @Test_Company_Balance_Assign_Credits_3   @Test_Company_Balance_Assign_Credits
                scenario: Asign credit accounts (error)
                given I am on the Balance company page ... passed in 18.08s 
e                when I select &#34;Assign Credit&#34; button ... passed in 4.133s 
                then I see the assign credits screen ... passed in 0.04207s 
                when I select the &#34;Identidad&#34; account ... passed in 6.34s 
                when I enter a valor &#34;-10&#34; in the avaliable balanace ... passed in 0.3332s 
                when I click the &#34;Allocate founds&#34; button ... passed in 3.292s 
                then I see the error message &#34;An error occurred while transferring balance among accounts&#34; in &#34;//div[@class=&#39;ant-notification-notice-description&#39;]&#34; ... failed in 2.074s 
@scenario.end
            ----------------------------------------------------------------------------------------------------
            ]]>
            </system-out>
        </testcase></testsuite>